Workbook
Name Slicer_casual: #N/A
Name Slicer_casual1: #N/A
Name Slicer_cnt: #N/A
Name Slicer_cnt1: #N/A
Name Slicer_Date: #N/A
Name Slicer_Date1: #N/A
Name Slicer_Hours: #N/A
Name Slicer_Hours1: #N/A
Name Slicer_registered: #N/A
Name Slicer_registered1: #N/A
Name Slicer_Temp: #N/A
Name Slicer_Temp1: #N/A
Name Slicer_Weekday: #N/A
Name Slicer_Weekday1: #N/A
Name Slicer_Wethers: #N/A
Name Slicer_Wethers1: #N/A

Sheet Datasheet_1
A1: instant | B1: Date | C1: season | D1: Year | E1: Month | F1: Hours | G1: Holiday | H1: Weekday | I1: Wethers | J1: Temp | L1: Date | M1: Year | N1: Day | O1: Date lenth | Q1: Formula | R1: Result
A2: 1 | B2: 40544 | C2: 1 | D2: 0 | E2: 1 | F2: 0 | G2: FALSE | H2: 6 | I2: 1 | J2: 0.24 | L2: =TEXT(B2,"yyyy-mm-dd") -> 2011-01-01 | M2: =LEFT(L2,4) -> 2011 | N2: =RIGHT(L2,2) -> 01 | O2: =LEN(L2) -> 10 | Q2: Total Temp | R2: =SUM(J2:J611) -> 120.1
A3: 2 | B3: 40544 | C3: 1 | D3: 0 | E3: 1 | F3: 1 | G3: FALSE | H3: 6 | I3: 1 | J3: 0.22 | L3: =TEXT(B3,"yyyy-mm-dd") -> 2011-01-01 | M3: =LEFT(L3,4) -> 2011 | N3: =RIGHT(L3,2) -> 01 | O3: =LEN(L3) -> 10 | Q3: Avg Temp | R3: =AVERAGE(J2:J611) -> 0.19688525
A4: 3 | B4: 40544 | C4: 1 | D4: 0 | E4: 1 | F4: 2 | G4: FALSE | H4: 6 | I4: 1 | J4: 0.22 | L4: =TEXT(B4,"yyyy-mm-dd") -> 2011-01-01 | M4: =LEFT(L4,4) -> 2011 | N4: =RIGHT(L4,2) -> 01 | O4: =LEN(L4) -> 10 | Q4: Record Count | R4: =COUNT(A2:A611) -> 610
A5: 4 | B5: 40544 | C5: 1 | D5: 0 | E5: 1 | F5: 3 | G5: FALSE | H5: 6 | I5: 1 | J5: 0.24 | L5: =TEXT(B5,"yyyy-mm-dd") -> 2011-01-01 | M5: =LEFT(L5,4) -> 2011 | N5: =RIGHT(L5,2) -> 01 | O5: =LEN(L5) -> 10 | Q5: Holiday count | R5: =COUNTIF(G2:G611,TRUE) -> 24
A6: 5 | B6: 40544 | C6: 1 | D6: 0 | E6: 1 | F6: 4 | G6: FALSE | H6: 6 | I6: 1 | J6: 0.24 | L6: =TEXT(B6,"yyyy-mm-dd") -> 2011-01-01 | M6: =LEFT(L6,4) -> 2011 | N6: =RIGHT(L6,2) -> 01 | O6: =LEN(L6) -> 10
A7: 6 | B7: 40544 | C7: 1 | D7: 0 | E7: 1 | F7: 5 | G7: FALSE | H7: 6 | I7: 2 | J7: 0.24 | L7: =TEXT(B7,"yyyy-mm-dd") -> 2011-01-01 | M7: =LEFT(L7,4) -> 2011 | N7: =RIGHT(L7,2) -> 01 | O7: =LEN(L7) -> 10
A8: 7 | B8: 40544 | C8: 1 | D8: 0 | E8: 1 | F8: 6 | G8: FALSE | H8: 6 | I8: 1 | J8: 0.22 | L8: =TEXT(B8,"yyyy-mm-dd") -> 2011-01-01 | M8: =LEFT(L8,4) -> 2011 | N8: =RIGHT(L8,2) -> 01 | O8: =LEN(L8) -> 10
A9: 8 | B9: 40544 | C9: 1 | D9: 0 | E9: 1 | F9: 7 | G9: FALSE | H9: 6 | I9: 1 | J9: 0.2 | L9: =TEXT(B9,"yyyy-mm-dd") -> 2011-01-01 | M9: =LEFT(L9,4) -> 2011 | N9: =RIGHT(L9,2) -> 01 | O9: =LEN(L9) -> 10
A10: 9 | B10: 40544 | C10: 1 | D10: 0 | E10: 1 | F10: 8 | G10: FALSE | H10: 6 | I10: 1 | J10: 0.24 | L10: =TEXT(B10,"yyyy-mm-dd") -> 2011-01-01 | M10: =LEFT(L10,4) -> 2011 | N10: =RIGHT(L10,2) -> 01 | O10: =LEN(L10) -> 10
A11: 10 | B11: 40544 | C11: 1 | D11: 0 | E11: 1 | F11: 9 | G11: FALSE | H11: 6 | I11: 1 | J11: 0.32 | L11: =TEXT(B11,"yyyy-mm-dd") -> 2011-01-01 | M11: =LEFT(L11,4) -> 2011 | N11: =RIGHT(L11,2) -> 01 | O11: =LEN(L11) -> 10
A12: 11 | B12: 40544 | C12: 1 | D12: 0 | E12: 1 | F12: 10 | G12: FALSE | H12: 6 | I12: 1 | J12: 0.38 | L12: =TEXT(B12,"yyyy-mm-dd") -> 2011-01-01 | M12: =LEFT(L12,4) -> 2011 | N12: =RIGHT(L12,2) -> 01 | O12: =LEN(L12) -> 10
A13: 12 | B13: 40544 | C13: 1 | D13: 0 | E13: 1 | F13: 11 | G13: FALSE | H13: 6 | I13: 1 | J13: 0.36 | L13: =TEXT(B13,"yyyy-mm-dd") -> 2011-01-01 | M13: =LEFT(L13,4) -> 2011 | N13: =RIGHT(L13,2) -> 01 | O13: =LEN(L13) -> 10
A14: 13 | B14: 40544 | C14: 1 | D14: 0 | E14: 1 | F14: 12 | G14: FALSE | H14: 6 | I14: 1 | J14: 0.42 | L14: =TEXT(B14,"yyyy-mm-dd") -> 2011-01-01 | M14: =LEFT(L14,4) -> 2011 | N14: =RIGHT(L14,2) -> 01 | O14: =LEN(L14) -> 10
A15: 14 | B15: 40544 | C15: 1 | D15: 0 | E15: 1 | F15: 13 | G15: FALSE | H15: 6 | I15: 2 | J15: 0.46 | L15: =TEXT(B15,"yyyy-mm-dd") -> 2011-01-01 | M15: =LEFT(L15,4) -> 2011 | N15: =RIGHT(L15,2) -> 01 | O15: =LEN(L15) -> 10
A16: 15 | B16: 40544 | C16: 1 | D16: 0 | E16: 1 | F16: 14 | G16: FALSE | H16: 6 | I16: 2 | J16: 0.46 | L16: =TEXT(B16,"yyyy-mm-dd") -> 2011-01-01 | M16: =LEFT(L16,4) -> 2011 | N16: =RIGHT(L16,2) -> 01 | O16: =LEN(L16) -> 10
A17: 16 | B17: 40544 | C17: 1 | D17: 0 | E17: 1 | F17: 15 | G17: FALSE | H17: 6 | I17: 2 | J17: 0.44 | L17: =TEXT(B17,"yyyy-mm-dd") -> 2011-01-01 | M17: =LEFT(L17,4) -> 2011 | N17: =RIGHT(L17,2) -> 01 | O17: =LEN(L17) -> 10
... A611: 610 | B611: 40571 | C611: 1 | D611: 0 | E611: 1 | F611: 15 | G611: FALSE | H611: 5 | I611: 2 | J611: 0.2 | L611: =TEXT(B611,"yyyy-mm-dd") -> 2011-01-28 | M611: =LEFT(L611,4) -> 2011 | N611: =RIGHT(L611,2) -> 28 | O611: =LEN(L611) -> 10

Sheet Datasheet_2
A1: Record ID | B1: instant | C1: Temp | D1: humudity | E1: windspeed | F1: casual | G1: registered | H1: cnt | I1: Record Tag | J1: Prefix | K1: Tag Ending | L1: Tag lenth | N1: Data Summary
A2: 439 | B2: 440 | C2: 0.2121 | D2: 0.55 | E2: 0.2836 | F2: 2 | G2: 247 | H2: 249 | I2: ="REC-"&TEXT(A2,"000") -> REC-439 | J2: =LEFT(I2,3) -> REC | K2: =RIGHT(I2,3) -> 439 | L2: =LEN(I2) -> 7 | N2: Total Riders | O2: =SUM($H$2:$H$611) -> 33898
A3: 555 | B3: 556 | C3: 0.1818 | D3: 0.74 | E3: 0.1343 | F3: 5 | G3: 233 | H3: 238 | I3: ="REC-"&TEXT(A3,"000") -> REC-555 | J3: =LEFT(I3,3) -> REC | K3: =RIGHT(I3,3) -> 555 | L3: =LEN(I3) -> 7 | N3: Avgrage Riders | O3: =AVERAGE($H$2:$H$611) -> 55.570492
A4: 565 | B4: 566 | C4: 0.3182 | D4: 0.49 | E4: 0.0896 | F4: 7 | G4: 218 | H4: 225 | I4: ="REC-"&TEXT(A4,"000") -> REC-565 | J4: =LEFT(I4,3) -> REC | K4: =RIGHT(I4,3) -> 565 | L4: =LEN(I4) -> 7 | N4: Record Count | O4: =COUNT($H$2:$H$611) -> 610
A5: 564 | B5: 565 | C5: 0.3333 | D5: 0.45 | E5: 0 | F5: 14 | G5: 208 | H5: 222 | I5: ="REC-"&TEXT(A5,"000") -> REC-564 | J5: =LEFT(I5,3) -> REC | K5: =RIGHT(I5,3) -> 564 | L5: =LEN(I5) -> 7 | N5: Highest Rider count | O5: =MAX($H$2:$H$611) -> 249
A6: 122 | B6: 123 | C6: 0.2273 | D6: 0.59 | E6: 0 | F6: 3 | G6: 216 | H6: 219 | I6: ="REC-"&TEXT(A6,"000") -> REC-122 | J6: =LEFT(I6,3) -> REC | K6: =RIGHT(I6,3) -> 122 | L6: =LEN(I6) -> 7
A7: 239 | B7: 240 | C7: 0.2121 | D7: 0.51 | E7: 0.0896 | F7: 3 | G7: 214 | H7: 217 | I7: ="REC-"&TEXT(A7,"000") -> REC-239 | J7: =LEFT(I7,3) -> REC | K7: =RIGHT(I7,3) -> 239 | L7: =LEN(I7) -> 7
A8: 463 | B8: 464 | C8: 0.1818 | D8: 0.47 | E8: 0.3284 | F8: 7 | G8: 210 | H8: 217 | I8: ="REC-"&TEXT(A8,"000") -> REC-463 | J8: =LEFT(I8,3) -> REC | K8: =RIGHT(I8,3) -> 463 | L8: =LEN(I8) -> 7
A9: 448 | B9: 449 | C9: 0.3182 | D9: 0.49 | E9: 0.1045 | F9: 8 | G9: 207 | H9: 215 | I9: ="REC-"&TEXT(A9,"000") -> REC-448 | J9: =LEFT(I9,3) -> REC | K9: =RIGHT(I9,3) -> 448 | L9: =LEN(I9) -> 7
A10: 85 | B10: 86 | C10: 0.2727 | D10: 0.48 | E10: 0.2239 | F10: 10 | G10: 202 | H10: 212 | I10: ="REC-"&TEXT(A10,"000") -> REC-085 | J10: =LEFT(I10,3) -> REC | K10: =RIGHT(I10,3) -> 085 | L10: =LEN(I10) -> 7
A11: 145 | B11: 146 | C11: 0.197 | D11: 0.51 | E11: 0.2537 | F11: 20 | G11: 190 | H11: 210 | I11: ="REC-"&TEXT(A11,"000") -> REC-145 | J11: =LEFT(I11,3) -> REC | K11: =RIGHT(I11,3) -> 145 | L11: =LEN(I11) -> 7
A12: 285 | B12: 286 | C12: 0.1364 | D12: 0.5 | E12: 0.194 | F12: 5 | G12: 197 | H12: 202 | I12: ="REC-"&TEXT(A12,"000") -> REC-285 | J12: =LEFT(I12,3) -> REC | K12: =RIGHT(I12,3) -> 285 | L12: =LEN(I12) -> 7
A13: 415 | B13: 416 | C13: 0.2576 | D13: 0.93 | E13: 0.1045 | F13: 1 | G13: 196 | H13: 197 | I13: ="REC-"&TEXT(A13,"000") -> REC-415 | J13: =LEFT(I13,3) -> REC | K13: =RIGHT(I13,3) -> 415 | L13: =LEN(I13) -> 7
A14: 424 | B14: 425 | C14: 0.3333 | D14: 0.57 | E14: 0.3284 | F14: 7 | G14: 190 | H14: 197 | I14: ="REC-"&TEXT(A14,"000") -> REC-424 | J14: =LEFT(I14,3) -> REC | K14: =RIGHT(I14,3) -> 424 | L14: =LEN(I14) -> 7
A15: 99 | B15: 100 | C15: 0.1818 | D15: 0.4 | E15: 0.2985 | F15: 3 | G15: 192 | H15: 195 | I15: ="REC-"&TEXT(A15,"000") -> REC-099 | J15: =LEFT(I15,3) -> REC | K15: =RIGHT(I15,3) -> 099 | L15: =LEN(I15) -> 7
A16: 108 | B16: 109 | C16: 0.2273 | D16: 0.38 | E16: 0.194 | F16: 4 | G16: 186 | H16: 190 | I16: ="REC-"&TEXT(A16,"000") -> REC-108 | J16: =LEFT(I16,3) -> REC | K16: =RIGHT(I16,3) -> 108 | L16: =LEN(I16) -> 7
A17: 217 | B17: 218 | C17: 0.1212 | D17: 0.5 | E17: 0.2836 | F17: 4 | G17: 184 | H17: 188 | I17: ="REC-"&TEXT(A17,"000") -> REC-217 | J17: =LEFT(I17,3) -> REC | K17: =RIGHT(I17,3) -> 217 | L17: =LEN(I17) -> 7
... A207: 127 | B207: 128 | C207: 0.2727 | D207: 0.35 | E207: 0.1045 | F207: 12 | G207: 55 | H207: 67 | I207: ="REC-"&TEXT(A207,"000") -> REC-127 | J207: =LEFT(I207,3) -> REC | K207: =RIGHT(I207,3) -> 127 | L207: =LEN(I207) -> 7
A208: 17 | B208: 18 | D208: 0.82 | E208: 0.2836 | F208: 15 | G208: 52 | H208: 67 | I208: ="REC-"&TEXT(A208,"000") -> REC-017 | J208: =LEFT(I208,3) -> REC | K208: =RIGHT(I208,3) -> 017 | L208: =LEN(I208) -> 7
A209: 148 | B209: 149 | C209: 0.197 | D209: 0.4 | E209: 0.2239 | F209: 19 | G209: 48 | H209: 67 | I209: ="REC-"&TEXT(A209,"000") -> REC-148 | J209: =LEFT(I209,3) -> REC | K209: =RIGHT(I209,3) -> 148 | L209: =LEN(I209) -> 7
A210: 470 | B210: 471 | C210: 0.1212 | D210: 0.26 | E210: 0.4478 | F210: 4 | G210: 61 | H210: 65 | I210: ="REC-"&TEXT(A210,"000") -> REC-470 | J210: =LEFT(I210,3) -> REC | K210: =RIGHT(I210,3) -> 470 | L210: =LEN(I210) -> 7
A211: 40 | B211: 41 | C211: 0.3333 | D211: 0.57 | E211: 0.194 | F211: 7 | G211: 58 | H211: 65 | I211: ="REC-"&TEXT(A211,"000") -> REC-040 | J211: =LEFT(I211,3) -> REC | K211: =RIGHT(I211,3) -> 040 | L211: =LEN(I211) -> 7
A212: 517 | B212: 518 | C212: 0.1364 | D212: 0.26 | E212: 0.3284 | F212: 9 | G212: 56 | H212: 65 | I212: ="REC-"&TEXT(A212,"000") -> REC-517 | J212: =LEFT(I212,3) -> REC | K212: =RIGHT(I212,3) -> 517 | L212: =LEN(I212) -> 7
A213: 83 | B213: 84 | C213: 0.2727 | D213: 0.52 | E213: 0.2537 | F213: 17 | G213: 48 | H213: 65 | I213: ="REC-"&TEXT(A213,"000") -> REC-083 | J213: =LEFT(I213,3) -> REC | K213: =RIGHT(I213,3) -> 083 | L213: =LEN(I213) -> 7
A214: 297 | B214: 298 | C214: 0.1515 | D214: 0.47 | E214: 0.2239 | F214: 0 | G214: 64 | H214: 64 | I214: ="REC-"&TEXT(A214,"000") -> REC-297 | J214: =LEFT(I214,3) -> REC | K214: =RIGHT(I214,3) -> 297 | L214: =LEN(I214) -> 7
A215: 52 | B215: 53 | C215: 0.1364 | D215: 0.5 | E215: 0.194 | F215: 1 | G215: 63 | H215: 64 | I215: ="REC-"&TEXT(A215,"000") -> REC-052 | J215: =LEFT(I215,3) -> REC | K215: =RIGHT(I215,3) -> 052 | L215: =LEN(I215) -> 7
A216: 314 | B216: 315 | C216: 0.2121 | D216: 0.41 | E216: 0.2836 | F216: 5 | G216: 59 | H216: 64 | I216: ="REC-"&TEXT(A216,"000") -> REC-314 | J216: =LEFT(I216,3) -> REC | K216: =RIGHT(I216,3) -> 314 | L216: =LEN(I216) -> 7
A217: 383 | B217: 384 | C217: 0.1515 | D217: 0.55 | E217: 0.194 | F217: 9 | G217: 55 | H217: 64 | I217: ="REC-"&TEXT(A217,"000") -> REC-383 | J217: =LEFT(I217,3) -> REC | K217: =RIGHT(I217,3) -> 383 | L217: =LEN(I217) -> 7
A218: 245 | B218: 246 | C218: 0.2273 | D218: 0.59 | E218: 0.0896 | F218: 3 | G218: 60 | H218: 63 | I218: ="REC-"&TEXT(A218,"000") -> REC-245 | J218: =LEFT(I218,3) -> REC | K218: =RIGHT(I218,3) -> 245 | L218: =LEN(I218) -> 7
A219: 489 | B219: 490 | C219: 0.0758 | D219: 0.38 | E219: 0.1343 | F219: 4 | G219: 59 | H219: 63 | I219: ="REC-"&TEXT(A219,"000") -> REC-489 | J219: =LEFT(I219,3) -> REC | K219: =RIGHT(I219,3) -> 489 | L219: =LEN(I219) -> 7
A220: 465 | B220: 466 | C220: 0.1667 | D220: 0.47 | E220: 0.4627 | F220: 6 | G220: 57 | H220: 63 | I220: ="REC-"&TEXT(A220,"000") -> REC-465 | J220: =LEFT(I220,3) -> REC | K220: =RIGHT(I220,3) -> 465 | L220: =LEN(I220) -> 7
... A233: 558 | B233: 559 | C233: 0.2424 | D233: 0.6 | E233: 0.1343 | F233: 6 | G233: 55 | H233: 61 | I233: ="REC-"&TEXT(A233,"000") -> REC-558 | J233: =LEFT(I233,3) -> REC | K233: =RIGHT(I233,3) -> 558 | L233: =LEN(I233) -> 7
A234: 58 | B234: 59 | D234: 0.35 | E234: 0.2836 | F234: 8 | G234: 53 | H234: 61 | I234: ="REC-"&TEXT(A234,"000") -> REC-058 | J234: =LEFT(I234,3) -> REC | K234: =RIGHT(I234,3) -> 058 | L234: =LEN(I234) -> 7
A235: 57 | B235: 58 | C235: 0.2121 | D235: 0.35 | E235: 0.2985 | F235: 13 | G235: 48 | H235: 61 | I235: ="REC-"&TEXT(A235,"000") -> REC-057 | J235: =LEFT(I235,3) -> REC | K235: =RIGHT(I235,3) -> 057 | L235: =LEN(I235) -> 7
A236: 367 | B236: 368 | C236: 0.197 | D236: 0.47 | E236: 0.1343 | F236: 14 | G236: 47 | H236: 61 | I236: ="REC-"&TEXT(A236,"000") -> REC-367 | J236: =LEFT(I236,3) -> REC | K236: =RIGHT(I236,3) -> 367 | L236: =LEN(I236) -> 7
A237: 601 | B237: 602 | C237: 0.197 | D237: 0.86 | E237: 0.0896 | F237: 2 | G237: 58 | H237: 60 | I237: ="REC-"&TEXT(A237,"000") -> REC-601 | J237: =LEFT(I237,3) -> REC | K237: =RIGHT(I237,3) -> 601 | L237: =LEN(I237) -> 7
A238: 391 | B238: 392 | C238: 0.1818 | D238: 0.59 | E238: 0.194 | F238: 2 | G238: 58 | H238: 60 | I238: ="REC-"&TEXT(A238,"000") -> REC-391 | J238: =LEFT(I238,3) -> REC | K238: =RIGHT(I238,3) -> 391 | L238: =LEN(I238) -> 7
A239: 292 | B239: 293 | C239: 0.2121 | D239: 0.38 | E239: 0.2985 | F239: 5 | G239: 55 | H239: 60 | I239: ="REC-"&TEXT(A239,"000") -> REC-292 | J239: =LEFT(I239,3) -> REC | K239: =RIGHT(I239,3) -> 292 | L239: =LEN(I239) -> 7
A240: 537 | B240: 538 | C240: 0.1364 | D240: 0.43 | E240: 0.2239 | F240: 6 | G240: 54 | H240: 60 | I240: ="REC-"&TEXT(A240,"000") -> REC-537 | J240: =LEFT(I240,3) -> REC | K240: =RIGHT(I240,3) -> 537 | L240: =LEN(I240) -> 7
A241: 334 | B241: 335 | C241: 0.197 | D241: 0.59 | E241: 0.1642 | F241: 2 | G241: 57 | H241: 59 | I241: ="REC-"&TEXT(A241,"000") -> REC-334 | J241: =LEFT(I241,3) -> REC | K241: =RIGHT(I241,3) -> 334 | L241: =LEN(I241) -> 7
...

Sheet Datasheet_3
A1: instant | B1: dteday | C1: season | D1: yr | E1: mnth | F1: hr | G1: holiday | H1: weekday | I1: weathersit | J1: temp | K1: atemp | L1: hum | M1: windspeed | N1: casual | O1: registered | P1: cnt | R1: Date text | S1: Left day | T1: Right year | U1: Length | W1: Rental summary
A2: 611 | B2: 40571 | C2: 1 | D2: 0 | E2: 1 | F2: 16 | G2: FALSE | H2: 5 | I2: 1 | J2: 0.22 | K2: 0.2727 | L2: 0.8 | M2: 0 | N2: 10 | O2: 70 | P2: 80 | R2: =TEXT(B2,"dd-mmm-yyyy") -> 28-Jan-2011 | S2: =LEFT(R2,2) -> 28 | T2: =RIGHT(R2,4) -> 2011 | U2: =LEN(R2) -> 11 | W2: Total rental sum | X2: =SUM(P2:P391) -> 24406
A3: 612 | B3: 40571 | C3: 1 | D3: 0 | E3: 1 | F3: 17 | G3: FALSE | H3: 5 | I3: 1 | J3: 0.24 | K3: 0.2424 | L3: 0.75 | M3: 0.1343 | N3: 2 | O3: 147 | P3: 149 | R3: =TEXT(B3,"dd-mmm-yyyy") -> 28-Jan-2011 | S3: =LEFT(R3,2) -> 28 | T3: =RIGHT(R3,4) -> 2011 | U3: =LEN(R3) -> 11 | W3: Avgarage rental | X3: =AVERAGE(P2:P391) -> 62.579487
A4: 613 | B4: 40571 | C4: 1 | D4: 0 | E4: 1 | F4: 18 | G4: FALSE | H4: 5 | I4: 1 | J4: 0.24 | K4: 0.2273 | L4: 0.75 | M4: 0.194 | N4: 2 | O4: 107 | P4: 109 | R4: =TEXT(B4,"dd-mmm-yyyy") -> 28-Jan-2011 | S4: =LEFT(R4,2) -> 28 | T4: =RIGHT(R4,4) -> 2011 | U4: =LEN(R4) -> 11 | W4: Records count | X4: =COUNT(P2:P391) -> 390
A5: 614 | B5: 40571 | C5: 1 | D5: 0 | E5: 1 | F5: 19 | G5: FALSE | H5: 5 | I5: 2 | J5: 0.24 | K5: 0.2424 | L5: 0.75 | M5: 0.1343 | N5: 5 | O5: 84 | P5: 89 | R5: =TEXT(B5,"dd-mmm-yyyy") -> 28-Jan-2011 | S5: =LEFT(R5,2) -> 28 | T5: =RIGHT(R5,4) -> 2011 | U5: =LEN(R5) -> 11 | W5: Highest rentals | X5: =MAX(P2:P391) -> 243
A6: 615 | B6: 40571 | C6: 1 | D6: 0 | E6: 1 | F6: 20 | G6: FALSE | H6: 5 | I6: 2 | J6: 0.24 | K6: 0.2273 | L6: 0.7 | M6: 0.194 | N6: 1 | O6: 61 | P6: 62 | R6: =TEXT(B6,"dd-mmm-yyyy") -> 28-Jan-2011 | S6: =LEFT(R6,2) -> 28 | T6: =RIGHT(R6,4) -> 2011 | U6: =LEN(R6) -> 11
A7: 616 | B7: 40571 | C7: 1 | D7: 0 | E7: 1 | F7: 21 | G7: FALSE | H7: 5 | I7: 2 | J7: 0.22 | K7: 0.2273 | L7: 0.75 | M7: 0.1343 | N7: 1 | O7: 57 | P7: 58 | R7: =TEXT(B7,"dd-mmm-yyyy") -> 28-Jan-2011 | S7: =LEFT(R7,2) -> 28 | T7: =RIGHT(R7,4) -> 2011 | U7: =LEN(R7) -> 11 | W7: Text Function example
A8: 617 | B8: 40571 | C8: 1 | D8: 0 | E8: 1 | F8: 22 | G8: FALSE | H8: 5 | I8: 1 | J8: 0.24 | K8: 0.2121 | L8: 0.65 | M8: 0.3582 | N8: 0 | O8: 26 | P8: 26 | R8: =TEXT(B8,"dd-mmm-yyyy") -> 28-Jan-2011 | S8: =LEFT(R8,2) -> 28 | T8: =RIGHT(R8,4) -> 2011 | U8: =LEN(R8) -> 11 | W8: Formatted first date | X8: =TEXT(B2,"dd-mmm-yyyy") -> 28-Jan-2011
A9: 618 | B9: 40571 | C9: 1 | D9: 0 | E9: 1 | F9: 23 | G9: FALSE | H9: 5 | I9: 1 | J9: 0.24 | K9: 0.2273 | L9: 0.6 | M9: 0.2239 | N9: 1 | O9: 22 | P9: 23 | R9: =TEXT(B9,"dd-mmm-yyyy") -> 28-Jan-2011 | S9: =LEFT(R9,2) -> 28 | T9: =RIGHT(R9,4) -> 2011 | U9: =LEN(R9) -> 11 | W9: Left day | X9: =LEFT(X8,2) -> 28
A10: 619 | B10: 40572 | C10: 1 | D10: 0 | E10: 1 | F10: 0 | G10: FALSE | H10: 6 | I10: 1 | J10: 0.22 | K10: 0.197 | L10: 0.64 | M10: 0.3582 | N10: 2 | O10: 26 | P10: 28 | R10: =TEXT(B10,"dd-mmm-yyyy") -> 29-Jan-2011 | S10: =LEFT(R10,2) -> 29 | T10: =RIGHT(R10,4) -> 2011 | U10: =LEN(R10) -> 11 | W10: Right year | X10: =RIGHT(X8,4) -> 2011
A11: 620 | B11: 40572 | C11: 1 | D11: 0 | E11: 1 | F11: 1 | G11: FALSE | H11: 6 | I11: 1 | J11: 0.22 | K11: 0.2273 | L11: 0.64 | M11: 0.194 | N11: 0 | O11: 20 | P11: 20 | R11: =TEXT(B11,"dd-mmm-yyyy") -> 29-Jan-2011 | S11: =LEFT(R11,2) -> 29 | T11: =RIGHT(R11,4) -> 2011 | U11: =LEN(R11) -> 11 | W11: Length | X11: =LEN(X8) -> 11
A12: 621 | B12: 40572 | C12: 1 | D12: 0 | E12: 1 | F12: 2 | G12: FALSE | H12: 6 | I12: 1 | J12: 0.22 | K12: 0.2273 | L12: 0.64 | M12: 0.1642 | N12: 0 | O12: 15 | P12: 15 | R12: =TEXT(B12,"dd-mmm-yyyy") -> 29-Jan-2011 | S12: =LEFT(R12,2) -> 29 | T12: =RIGHT(R12,4) -> 2011 | U12: =LEN(R12) -> 11
A13: 622 | B13: 40572 | C13: 1 | D13: 0 | E13: 1 | F13: 3 | G13: FALSE | H13: 6 | I13: 1 | J13: 0.2 | K13: 0.2121 | L13: 0.64 | M13: 0.1343 | N13: 3 | O13: 5 | P13: 8 | R13: =TEXT(B13,"dd-mmm-yyyy") -> 29-Jan-2011 | S13: =LEFT(R13,2) -> 29 | T13: =RIGHT(R13,4) -> 2011 | U13: =LEN(R13) -> 11
A14: 623 | B14: 40572 | C14: 1 | D14: 0 | E14: 1 | F14: 4 | G14: FALSE | H14: 6 | I14: 1 | J14: 0.16 | K14: 0.1818 | L14: 0.69 | M14: 0.1045 | N14: 1 | O14: 2 | P14: 3 | R14: =TEXT(B14,"dd-mmm-yyyy") -> 29-Jan-2011 | S14: =LEFT(R14,2) -> 29 | T14: =RIGHT(R14,4) -> 2011 | U14: =LEN(R14) -> 11
A15: 624 | B15: 40572 | C15: 1 | D15: 0 | E15: 1 | F15: 6 | G15: FALSE | H15: 6 | I15: 1 | J15: 0.16 | K15: 0.1818 | L15: 0.64 | M15: 0.1343 | N15: 0 | O15: 2 | P15: 2 | R15: =TEXT(B15,"dd-mmm-yyyy") -> 29-Jan-2011 | S15: =LEFT(R15,2) -> 29 | T15: =RIGHT(R15,4) -> 2011 | U15: =LEN(R15) -> 11
A16: 625 | B16: 40572 | C16: 1 | D16: 0 | E16: 1 | F16: 7 | G16: FALSE | H16: 6 | I16: 1 | J16: 0.16 | K16: 0.1818 | L16: 0.59 | M16: 0.1045 | N16: 1 | O16: 4 | P16: 5 | R16: =TEXT(B16,"dd-mmm-yyyy") -> 29-Jan-2011 | S16: =LEFT(R16,2) -> 29 | T16: =RIGHT(R16,4) -> 2011 | U16: =LEN(R16) -> 11
A17: 626 | B17: 40572 | C17: 1 | D17: 0 | E17: 1 | F17: 8 | G17: FALSE | H17: 6 | I17: 1 | J17: 0.18 | K17: 0.197 | L17: 0.55 | M17: 0.1642 | N17: 3 | O17: 31 | P17: 34 | R17: =TEXT(B17,"dd-mmm-yyyy") -> 29-Jan-2011 | S17: =LEFT(R17,2) -> 29 | T17: =RIGHT(R17,4) -> 2011 | U17: =LEN(R17) -> 11
A18: 627 | B18: 40572 | C18: 1 | D18: 0 | E18: 1 | F18: 9 | G18: FALSE | H18: 6 | I18: 1 | J18: 0.18 | K18: 0.2121 | L18: 0.59 | M18: 0.0896 | N18: 0 | O18: 34 | P18: 34 | R18: =TEXT(B18,"dd-mmm-yyyy") -> 29-Jan-2011 | S18: =LEFT(R18,2) -> 29 | T18: =RIGHT(R18,4) -> 2011 | U18: =LEN(R18) -> 11
A19: 628 | B19: 40572 | C19: 1 | D19: 0 | E19: 1 | F19: 10 | G19: FALSE | H19: 6 | I19: 2 | J19: 0.18 | K19: 0.2121 | L19: 0.64 | M19: 0.1045 | N19: 4 | O19: 51 | P19: 55 | R19: =TEXT(B19,"dd-mmm-yyyy") -> 29-Jan-2011 | S19: =LEFT(R19,2) -> 29 | T19: =RIGHT(R19,4) -> 2011 | U19: =LEN(R19) -> 11
A20: 629 | B20: 40572 | C20: 1 | D20: 0 | E20: 1 | F20: 11 | G20: FALSE | H20: 6 | I20: 2 | J20: 0.18 | K20: 0.197 | L20: 0.64 | M20: 0.1343 | N20: 4 | O20: 60 | P20: 64 | R20: =TEXT(B20,"dd-mmm-yyyy") -> 29-Jan-2011 | S20: =LEFT(R20,2) -> 29 | T20: =RIGHT(R20,4) -> 2011 | U20: =LEN(R20) -> 11
A21: 630 | B21: 40572 | C21: 1 | D21: 0 | E21: 1 | F21: 12 | G21: FALSE | H21: 6 | I21: 2 | J21: 0.2 | K21: 0.197 | L21: 0.59 | M21: 0.194 | N21: 12 | O21: 66 | P21: 78 | R21: =TEXT(B21,"dd-mmm-yyyy") -> 29-Jan-2011 | S21: =LEFT(R21,2) -> 29 | T21: =RIGHT(R21,4) -> 2011 | U21: =LEN(R21) -> 11
A22: 631 | B22: 40572 | C22: 1 | D22: 0 | E22: 1 | F22: 13 | G22: FALSE | H22: 6 | I22: 2 | J22: 0.22 | K22: 0.2273 | L22: 0.55 | M22: 0.1642 | N22: 9 | O22: 56 | P22: 65 | R22: =TEXT(B22,"dd-mmm-yyyy") -> 29-Jan-2011 | S22: =LEFT(R22,2) -> 29 | T22: =RIGHT(R22,4) -> 2011 | U22: =LEN(R22) -> 11
A23: 632 | B23: 40572 | C23: 1 | D23: 0 | E23: 1 | F23: 14 | G23: FALSE | H23: 6 | I23: 2 | J23: 0.22 | K23: 0.2273 | L23: 0.6 | M23: 0.1343 | N23: 10 | O23: 89 | P23: 99 | R23: =TEXT(B23,"dd-mmm-yyyy") -> 29-Jan-2011 | S23: =LEFT(R23,2) -> 29 | T23: =RIGHT(R23,4) -> 2011 | U23: =LEN(R23) -> 11
... A391: 1000 | B391: 40588 | C391: 1 | D391: 0 | E391: 2 | F391: 7 | G391: FALSE | H391: 1 | I391: 1 | J391: 0.34 | K391: 0.303 | L391: 0.46 | M391: 0.2985 | N391: 2 | O391: 96 | P391: 98 | R391: =TEXT(B391,"dd-mmm-yyyy") -> 14-Feb-2011 | S391: =LEFT(R391,2) -> 14 | T391: =RIGHT(R391,4) -> 2011 | U391: =LEN(R391) -> 11

Sheet Datasheet A (1+2)
A1: instant | B1: Date | C1: season | D1: Year | E1: Month | F1: Hours | G1: Holiday | H1: Weekday | I1: Wethers | J1: Temp | K1: atemp | L1: hum | M1: windspeed | N1: casual | O1: registered | P1: cnt
A2: 1 | B2: 40544 | C2: 1 | D2: 0 | E2: 1 | F2: 0 | G2: FALSE | H2: 6 | I2: 1 | J2: 0.24 | K2: 0.2879 | L2: 0.81 | M2: 0 | N2: 3 | O2: 13 | P2: 16 | R2: Holiday | S2: (All)
A3: 2 | B3: 40544 | C3: 1 | D3: 0 | E3: 1 | F3: 1 | G3: FALSE | H3: 6 | I3: 1 | J3: 0.22 | K3: 0.2727 | L3: 0.8 | M3: 0 | N3: 8 | O3: 32 | P3: 40 | R3: instant | S3: (All)
A4: 3 | B4: 40544 | C4: 1 | D4: 0 | E4: 1 | F4: 2 | G4: FALSE | H4: 6 | I4: 1 | J4: 0.22 | K4: 0.2727 | L4: 0.8 | M4: 0 | N4: 5 | O4: 27 | P4: 32
A5: 4 | B5: 40544 | C5: 1 | D5: 0 | E5: 1 | F5: 3 | G5: FALSE | H5: 6 | I5: 1 | J5: 0.24 | K5: 0.2879 | L5: 0.75 | M5: 0 | N5: 3 | O5: 10 | P5: 13 | R5: Row Labels | S5: Sum of casual | T5: Sum of registered | U5: Sum of cnt
A6: 5 | B6: 40544 | C6: 1 | D6: 0 | E6: 1 | F6: 4 | G6: FALSE | H6: 6 | I6: 1 | J6: 0.24 | K6: 0.2879 | L6: 0.75 | M6: 0 | N6: 0 | O6: 1 | P6: 1 | R6: 40544 | S6: 331 | T6: 654 | U6: 985
A7: 6 | B7: 40544 | C7: 1 | D7: 0 | E7: 1 | F7: 5 | G7: FALSE | H7: 6 | I7: 2 | J7: 0.24 | K7: 0.2576 | L7: 0.75 | M7: 0.0896 | N7: 0 | O7: 1 | P7: 1 | R7: 40545 | S7: 131 | T7: 670 | U7: 801
A8: 7 | B8: 40544 | C8: 1 | D8: 0 | E8: 1 | F8: 6 | G8: FALSE | H8: 6 | I8: 1 | J8: 0.22 | K8: 0.2727 | L8: 0.8 | M8: 0 | N8: 2 | O8: 0 | P8: 2 | R8: 40546 | S8: 120 | T8: 1229 | U8: 1349
A9: 8 | B9: 40544 | C9: 1 | D9: 0 | E9: 1 | F9: 7 | G9: FALSE | H9: 6 | I9: 1 | J9: 0.2 | K9: 0.2576 | L9: 0.86 | M9: 0 | N9: 1 | O9: 2 | P9: 3 | R9: 40547 | S9: 108 | T9: 1454 | U9: 1562
A10: 9 | B10: 40544 | C10: 1 | D10: 0 | E10: 1 | F10: 8 | G10: FALSE | H10: 6 | I10: 1 | J10: 0.24 | K10: 0 | L10: 0.75 | M10: 0 | N10: 1 | O10: 7 | P10: 8 | R10: 40548 | S10: 82 | T10: 1518 | U10: 1600
A11: 10 | B11: 40544 | C11: 1 | D11: 0 | E11: 1 | F11: 9 | G11: FALSE | H11: 6 | I11: 1 | J11: 0.32 | K11: 0.3485 | L11: 0.76 | M11: 0 | N11: 8 | O11: 6 | P11: 14 | R11: 40549 | S11: 88 | T11: 1518 | U11: 1606
A12: 11 | B12: 40544 | C12: 1 | D12: 0 | E12: 1 | F12: 10 | G12: FALSE | H12: 6 | I12: 1 | J12: 0.38 | K12: 0.3939 | L12: 0.76 | M12: 0.2537 | N12: 12 | O12: 24 | P12: 36 | R12: 40550 | S12: 148 | T12: 1362 | U12: 1510
A13: 12 | B13: 40544 | C13: 1 | D13: 0 | E13: 1 | F13: 11 | G13: FALSE | H13: 6 | I13: 1 | J13: 0.36 | K13: 0.3333 | L13: 0.81 | M13: 0.2836 | N13: 26 | O13: 30 | P13: 56 | R13: 40551 | S13: 68 | T13: 891 | U13: 959
A14: 13 | B14: 40544 | C14: 1 | D14: 0 | E14: 1 | F14: 12 | G14: FALSE | H14: 6 | I14: 1 | J14: 0.42 | K14: 0.4242 | L14: 0.77 | M14: 0.2836 | N14: 29 | O14: 55 | P14: 84 | R14: 40552 | S14: 54 | T14: 768 | U14: 822
A15: 14 | B15: 40544 | C15: 1 | D15: 0 | E15: 1 | F15: 13 | G15: FALSE | H15: 6 | I15: 2 | J15: 0.46 | K15: 0.4545 | L15: 0.72 | M15: 0.2985 | N15: 47 | O15: 47 | P15: 94 | R15: 40553 | S15: 41 | T15: 1280 | U15: 1321
A16: 15 | B16: 40544 | C16: 1 | D16: 0 | E16: 1 | F16: 14 | G16: FALSE | H16: 6 | I16: 2 | J16: 0.46 | K16: 0.4545 | L16: 0.72 | M16: 0.2836 | N16: 35 | O16: 71 | P16: 106 | R16: 40554 | S16: 43 | T16: 1220 | U16: 1263
A17: 16 | B17: 40544 | C17: 1 | D17: 0 | E17: 1 | F17: 15 | G17: FALSE | H17: 6 | I17: 2 | J17: 0.44 | K17: 0.4394 | L17: 0.77 | M17: 0.2985 | N17: 40 | O17: 70 | P17: 110 | R17: 40555 | S17: 25 | T17: 1137 | U17: 1162
... A33: 32 | B33: 40545 | C33: 1 | D33: 0 | E33: 1 | F33: 8 | G33: FALSE | H33: 0 | I33: 3 | J33: 0.4 | K33: 0.4091 | L33: 0.71 | M33: 0.2239 | N33: 0 | O33: 8 | P33: 8 | R33: 40571 | S33: 16 | T33: 555 | U33: 571
A34: 33 | B34: 40545 | C34: 1 | D34: 0 | E34: 1 | F34: 9 | G34: FALSE | H34: 0 | I34: 2 | J34: 0.38 | K34: 0 | L34: 0.76 | M34: 0.2239 | N34: 1 | O34: 19 | P34: 20 | R34: Grand Total | S34: 2746 | T34: 31152 | U34: 33898
A35: 34 | B35: 40545 | C35: 1 | D35: 0 | E35: 1 | F35: 10 | G35: FALSE | H35: 0 | I35: 2 | J35: 0.36 | K35: 0.3485 | L35: 0.81 | M35: 0.2239 | N35: 7 | O35: 46 | P35: 53
A36: 35 | B36: 40545 | C36: 1 | D36: 0 | E36: 1 | F36: 11 | G36: FALSE | H36: 0 | I36: 2 | J36: 0.36 | K36: 0.3333 | L36: 0.71 | M36: 0.2537 | N36: 16 | O36: 54 | P36: 70
A37: 36 | B37: 40545 | C37: 1 | D37: 0 | E37: 1 | F37: 12 | G37: FALSE | H37: 0 | I37: 2 | J37: 0.36 | K37: 0.3333 | L37: 0.66 | M37: 0.2985 | N37: 20 | O37: 73 | P37: 93
A38: 37 | B38: 40545 | C38: 1 | D38: 0 | E38: 1 | F38: 13 | G38: FALSE | H38: 0 | I38: 2 | J38: 0.36 | K38: 0.3485 | L38: 0.66 | M38: 0.1343 | N38: 11 | O38: 64 | P38: 75
A39: 38 | B39: 40545 | C39: 1 | D39: 0 | E39: 1 | F39: 14 | G39: FALSE | H39: 0 | I39: 3 | J39: 0.36 | K39: 0 | L39: 0.76 | M39: 0.194 | N39: 4 | O39: 55 | P39: 59
A40: 39 | B40: 40545 | C40: 1 | D40: 0 | E40: 1 | F40: 15 | G40: FALSE | H40: 0 | I40: 3 | J40: 0.34 | K40: 0.3333 | L40: 0.81 | M40: 0.1642 | N40: 19 | O40: 55 | P40: 74
A41: 40 | B41: 40545 | C41: 1 | D41: 0 | E41: 1 | F41: 16 | G41: FALSE | H41: 0 | I41: 3 | J41: 0.34 | K41: 0.3333 | L41: 0.71 | M41: 0.1642 | N41: 9 | O41: 67 | P41: 76
A42: 41 | B42: 40545 | C42: 1 | D42: 0 | E42: 1 | F42: 17 | G42: FALSE | H42: 0 | I42: 1 | J42: 0.34 | K42: 0.3333 | L42: 0.57 | M42: 0.194 | N42: 7 | O42: 58 | P42: 65
A43: 42 | B43: 40545 | C43: 1 | D43: 0 | E43: 1 | F43: 18 | G43: FALSE | H43: 0 | I43: 2 | J43: 0.36 | K43: 0.3333 | L43: 0.46 | M43: 0.3284 | N43: 10 | O43: 43 | P43: 53
A44: 43 | B44: 40545 | C44: 1 | D44: 0 | E44: 1 | F44: 19 | G44: FALSE | H44: 0 | I44: 1 | J44: 0.32 | K44: 0.2879 | L44: 0.42 | M44: 0.4478 | N44: 1 | O44: 29 | P44: 30
A45: 44 | B45: 40545 | C45: 1 | D45: 0 | E45: 1 | F45: 20 | G45: FALSE | H45: 0 | I45: 1 | J45: 0.3 | K45: 0 | L45: 0.39 | M45: 0.3582 | N45: 5 | O45: 17 | P45: 22
A46: 45 | B46: 40545 | C46: 1 | D46: 0 | E46: 1 | F46: 21 | G46: FALSE | H46: 0 | I46: 1 | J46: 0.26 | K46: 0.2273 | L46: 0.44 | M46: 0.3284 | N46: 11 | O46: 20 | P46: 31
... A611: 610 | B611: 40571 | C611: 1 | D611: 0 | E611: 1 | F611: 15 | G611: FALSE | H611: 5 | I611: 2 | J611: 0.2 | K611: 0.2576 | L611: 0.86 | M611: 0 | N611: 1 | O611: 40 | P611: 41

Sheet Datasheet B(A+3)
A1: instant | B1: Date | C1: season | D1: Year | E1: Month | F1: Hours | G1: Holiday | H1: Weekday | I1: Wethers | J1: Temp | K1: atemp | L1: hum | M1: windspeed | N1: casual | O1: registered | P1: cnt
A2: 1 | B2: 40544 | C2: 1 | D2: 0 | E2: Jan | F2: 0 | G2: FALSE | H2: Saturday | I2: Clear | J2: 0.24 | K2: 0.2879 | L2: 0.81 | M2: 0 | N2: 3 | O2: 13 | P2: 16 | R2: Month | S2: (All)
A3: 2 | B3: 40544 | C3: 1 | D3: 0 | E3: Jan | F3: 1 | G3: FALSE | H3: Saturday | I3: Clear | J3: 0.22 | K3: 0.2727 | L3: 0.8 | M3: 0 | N3: 8 | O3: 32 | P3: 40 | R3: instant | S3: (All)
A4: 3 | B4: 40544 | C4: 1 | D4: 0 | E4: Jan | F4: 2 | G4: FALSE | H4: Saturday | I4: Clear | J4: 0.22 | K4: 0.2727 | L4: 0.8 | M4: 0 | N4: 5 | O4: 27 | P4: 32
A5: 4 | B5: 40544 | C5: 1 | D5: 0 | E5: Jan | F5: 3 | G5: FALSE | H5: Saturday | I5: Clear | J5: 0.24 | K5: 0.2879 | L5: 0.75 | M5: 0 | N5: 3 | O5: 10 | P5: 13 | R5: Row Labels | S5: Sum of Hours | T5: Sum of casual | U5: Sum of cnt | V5: Sum of registered
A6: 5 | B6: 40544 | C6: 1 | D6: 0 | E6: Jan | F6: 4 | G6: FALSE | H6: Saturday | I6: Clear | J6: 0.24 | K6: 0.2879 | L6: 0.75 | M6: 0 | N6: 0 | O6: 1 | P6: 1 | R6: 1-Jan | S6: 276 | T6: 331 | U6: 985 | V6: 654
A7: 6 | B7: 40544 | C7: 1 | D7: 0 | E7: Jan | F7: 5 | G7: FALSE | H7: Saturday | I7: Mist | J7: 0.24 | K7: 0.2576 | L7: 0.75 | M7: 0.0896 | N7: 0 | O7: 1 | P7: 1 | R7: 2-Jan | S7: 271 | T7: 131 | U7: 801 | V7: 670
A8: 7 | B8: 40544 | C8: 1 | D8: 0 | E8: Jan | F8: 6 | G8: FALSE | H8: Saturday | I8: Clear | J8: 0.22 | K8: 0.2727 | L8: 0.8 | M8: 0 | N8: 2 | O8: 0 | P8: 2 | R8: 3-Jan | S8: 271 | T8: 120 | U8: 1349 | V8: 1229
A9: 8 | B9: 40544 | C9: 1 | D9: 0 | E9: Jan | F9: 7 | G9: FALSE | H9: Saturday | I9: Clear | J9: 0.2 | K9: 0.2576 | L9: 0.86 | M9: 0 | N9: 1 | O9: 2 | P9: 3 | R9: 4-Jan | S9: 273 | T9: 108 | U9: 1562 | V9: 1454
A10: 9 | B10: 40544 | C10: 1 | D10: 0 | E10: Jan | F10: 8 | G10: FALSE | H10: Saturday | I10: Clear | J10: 0.24 | K10: 0 | L10: 0.75 | M10: 0 | N10: 1 | O10: 7 | P10: 8 | R10: 5-Jan | S10: 273 | T10: 82 | U10: 1600 | V10: 1518
A11: 10 | B11: 40544 | C11: 1 | D11: 0 | E11: Jan | F11: 9 | G11: FALSE | H11: Saturday | I11: Clear | J11: 0.32 | K11: 0.3485 | L11: 0.76 | M11: 0 | N11: 8 | O11: 6 | P11: 14 | R11: 6-Jan | S11: 273 | T11: 88 | U11: 1606 | V11: 1518
A12: 11 | B12: 40544 | C12: 1 | D12: 0 | E12: Jan | F12: 10 | G12: FALSE | H12: Saturday | I12: Clear | J12: 0.38 | K12: 0.3939 | L12: 0.76 | M12: 0.2537 | N12: 12 | O12: 24 | P12: 36 | R12: 7-Jan | S12: 273 | T12: 148 | U12: 1510 | V12: 1362
A13: 12 | B13: 40544 | C13: 1 | D13: 0 | E13: Jan | F13: 11 | G13: FALSE | H13: Saturday | I13: Clear | J13: 0.36 | K13: 0.3333 | L13: 0.81 | M13: 0.2836 | N13: 26 | O13: 30 | P13: 56 | R13: 8-Jan | S13: 276 | T13: 68 | U13: 959 | V13: 891
A14: 13 | B14: 40544 | C14: 1 | D14: 0 | E14: Jan | F14: 12 | G14: FALSE | H14: Saturday | I14: Clear | J14: 0.42 | K14: 0.4242 | L14: 0.77 | M14: 0.2836 | N14: 29 | O14: 55 | P14: 84 | R14: 9-Jan | S14: 276 | T14: 54 | U14: 822 | V14: 768
A15: 14 | B15: 40544 | C15: 1 | D15: 0 | E15: Jan | F15: 13 | G15: FALSE | H15: Saturday | I15: Mist | J15: 0.46 | K15: 0.4545 | L15: 0.72 | M15: 0.2985 | N15: 47 | O15: 47 | P15: 94 | R15: 10-Jan | S15: 276 | T15: 41 | U15: 1321 | V15: 1280
A16: 15 | B16: 40544 | C16: 1 | D16: 0 | E16: Jan | F16: 14 | G16: FALSE | H16: Saturday | I16: Mist | J16: 0.46 | K16: 0.4545 | L16: 0.72 | M16: 0.2836 | N16: 35 | O16: 71 | P16: 106 | R16: 11-Jan | S16: 269 | T16: 43 | U16: 1263 | V16: 1220
A17: 16 | B17: 40544 | C17: 1 | D17: 0 | E17: Jan | F17: 15 | G17: FALSE | H17: Saturday | I17: Mist | J17: 0.44 | K17: 0.4394 | L17: 0.77 | M17: 0.2985 | N17: 40 | O17: 70 | P17: 110 | R17: 12-Jan | S17: 269 | T17: 25 | U17: 1162 | V17: 1137
... A51: 50 | B51: 40546 | C51: 1 | D51: 0 | E51: Jan | F51: 4 | G51: FALSE | H51: Monday | I51: Clear | J51: 0.16 | K51: 0.1364 | L51: 0.47 | M51: 0.3881 | N51: 0 | O51: 1 | P51: 1 | R51: Grand Total | S51: 11753 | T51: 4921 | U51: 58304 | V51: 53383
A52: 51 | B52: 40546 | C52: 1 | D52: 0 | E52: Jan | F52: 5 | G52: FALSE | H52: Monday | I52: Clear | J52: 0.16 | K52: 0.1364 | L52: 0.47 | M52: 0.2836 | N52: 0 | O52: 3 | P52: 3
A53: 52 | B53: 40546 | C53: 1 | D53: 0 | E53: Jan | F53: 6 | G53: FALSE | H53: Monday | I53: Clear | J53: 0.14 | K53: 0.1061 | L53: 0.5 | M53: 0.3881 | N53: 0 | O53: 30 | P53: 30
A54: 53 | B54: 40546 | C54: 1 | D54: 0 | E54: Jan | F54: 7 | G54: FALSE | H54: Monday | I54: Clear | J54: 0.14 | K54: 0.1364 | L54: 0.5 | M54: 0.194 | N54: 1 | O54: 63 | P54: 64
A55: 54 | B55: 40546 | C55: 1 | D55: 0 | E55: Jan | F55: 8 | G55: FALSE | H55: Monday | I55: Clear | J55: 0.14 | K55: 0.1212 | L55: 0.5 | M55: 0.2836 | N55: 1 | O55: 153 | P55: 154
A56: 55 | B56: 40546 | C56: 1 | D56: 0 | E56: Jan | F56: 9 | G56: FALSE | H56: Monday | I56: Clear | J56: 0.16 | K56: 0.1364 | L56: 0.43 | M56: 0.3881 | N56: 7 | O56: 81 | P56: 88
A57: 56 | B57: 40546 | C57: 1 | D57: 0 | E57: Jan | F57: 10 | G57: FALSE | H57: Monday | I57: Clear | J57: 0.18 | K57: 0.1667 | L57: 0.43 | M57: 0.2537 | N57: 11 | O57: 33 | P57: 44
A58: 57 | B58: 40546 | C58: 1 | D58: 0 | E58: Jan | F58: 11 | G58: FALSE | H58: Monday | I58: Clear | J58: 0.2 | K58: 0.1818 | L58: 0.4 | M58: 0.3284 | N58: 10 | O58: 41 | P58: 51
A59: 58 | B59: 40546 | C59: 1 | D59: 0 | E59: Jan | F59: 12 | G59: FALSE | H59: Monday | I59: Clear | J59: 0.22 | K59: 0.2121 | L59: 0.35 | M59: 0.2985 | N59: 13 | O59: 48 | P59: 61
A60: 59 | B60: 40546 | C60: 1 | D60: 0 | E60: Jan | F60: 13 | G60: FALSE | H60: Monday | I60: Clear | J60: 0.24 | K60: 0 | L60: 0.35 | M60: 0.2836 | N60: 8 | O60: 53 | P60: 61
A61: 60 | B61: 40546 | C61: 1 | D61: 0 | E61: Jan | F61: 14 | G61: FALSE | H61: Monday | I61: Clear | J61: 0.26 | K61: 0.2424 | L61: 0.3 | M61: 0.2836 | N61: 11 | O61: 66 | P61: 77
A62: 61 | B62: 40546 | C62: 1 | D62: 0 | E62: Jan | F62: 15 | G62: FALSE | H62: Monday | I62: Clear | J62: 0.26 | K62: 0.2424 | L62: 0.3 | M62: 0.2537 | N62: 14 | O62: 58 | P62: 72
A63: 62 | B63: 40546 | C63: 1 | D63: 0 | E63: Jan | F63: 16 | G63: FALSE | H63: Monday | I63: Clear | J63: 0.26 | K63: 0.2424 | L63: 0.3 | M63: 0.2537 | N63: 9 | O63: 67 | P63: 76
... A1001: 1000 | B1001: 40588 | C1001: 1 | D1001: 0 | E1001: Feb | F1001: 7 | G1001: FALSE | H1001: Monday | I1001: Clear | J1001: 0.34 | K1001: 0.303 | L1001: 0.46 | M1001: 0.2985 | N1001: 2 | O1001: 96 | P1001: 98

Sheet Original Data
A1: instant | B1: Date | C1: season | D1: Year | E1: Month | F1: Hours | G1: Holiday | H1: Weekday | I1: Weathers | J1: Temp | K1: atemp | L1: hum | M1: windspeed | N1: casual | O1: registered | P1: cnt
A2: 1 | B2: 40544 | C2: 1 | D2: 0 | E2: Jan | F2: 0 | G2: FALSE | H2: Saturday | I2: Clear | J2: 0.24 | K2: 0.2879 | L2: 0.81 | M2: 0 | N2: 3 | O2: 13 | P2: 16
A3: 2 | B3: 40544 | C3: 1 | D3: 0 | E3: Jan | F3: 1 | G3: FALSE | H3: Saturday | I3: Clear | J3: 0.22 | K3: 0.2727 | L3: 0.8 | M3: 0 | N3: 8 | O3: 32 | P3: 40
A4: 3 | B4: 40544 | C4: 1 | D4: 0 | E4: Jan | F4: 2 | G4: FALSE | H4: Saturday | I4: Clear | J4: 0.22 | K4: 0.2727 | L4: 0.8 | M4: 0 | N4: 5 | O4: 27 | P4: 32
A5: 4 | B5: 40544 | C5: 1 | D5: 0 | E5: Jan | F5: 3 | G5: FALSE | H5: Saturday | I5: Clear | J5: 0.24 | K5: 0.2879 | L5: 0.75 | M5: 0 | N5: 3 | O5: 10 | P5: 13
A6: 5 | B6: 40544 | C6: 1 | D6: 0 | E6: Jan | F6: 4 | G6: FALSE | H6: Saturday | I6: Clear | J6: 0.24 | K6: 0.2879 | L6: 0.75 | M6: 0 | N6: 0 | O6: 1 | P6: 1
A7: 6 | B7: 40544 | C7: 1 | D7: 0 | E7: Jan | F7: 5 | G7: FALSE | H7: Saturday | I7: Mist | J7: 0.24 | K7: 0.2576 | L7: 0.75 | M7: 0.0896 | N7: 0 | O7: 1 | P7: 1
A8: 7 | B8: 40544 | C8: 1 | D8: 0 | E8: Jan | F8: 6 | G8: FALSE | H8: Saturday | I8: Clear | J8: 0.22 | K8: 0.2727 | L8: 0.8 | M8: 0 | N8: 2 | O8: 0 | P8: 2
A9: 8 | B9: 40544 | C9: 1 | D9: 0 | E9: Jan | F9: 7 | G9: FALSE | H9: Saturday | I9: Clear | J9: 0.2 | K9: 0.2576 | L9: 0.86 | M9: 0 | N9: 1 | O9: 2 | P9: 3
A10: 9 | B10: 40544 | C10: 1 | D10: 0 | E10: Jan | F10: 8 | G10: FALSE | H10: Saturday | I10: Clear | J10: 0.24 | K10: 0 | L10: 0.75 | M10: 0 | N10: 1 | O10: 7 | P10: 8
A11: 10 | B11: 40544 | C11: 1 | D11: 0 | E11: Jan | F11: 9 | G11: FALSE | H11: Saturday | I11: Clear | J11: 0.32 | K11: 0.3485 | L11: 0.76 | M11: 0 | N11: 8 | O11: 6 | P11: 14
A12: 11 | B12: 40544 | C12: 1 | D12: 0 | E12: Jan | F12: 10 | G12: FALSE | H12: Saturday | I12: Clear | J12: 0.38 | K12: 0.3939 | L12: 0.76 | M12: 0.2537 | N12: 12 | O12: 24 | P12: 36
A13: 12 | B13: 40544 | C13: 1 | D13: 0 | E13: Jan | F13: 11 | G13: FALSE | H13: Saturday | I13: Clear | J13: 0.36 | K13: 0.3333 | L13: 0.81 | M13: 0.2836 | N13: 26 | O13: 30 | P13: 56
... A1001: 1000 | B1001: 40588 | C1001: 1 | D1001: 0 | E1001: Feb | F1001: 7 | G1001: FALSE | H1001: Monday | I1001: Clear | J1001: 0.34 | K1001: 0.303 | L1001: 0.46 | M1001: 0.2985 | N1001: 2 | O1001: 96 | P1001: 98

Sheet Statistical & Correlation
B3: TOTAL CASUAL USERS | D3: TOTAL RIDES DEMAND | F3: AVG HOURLY DEMAND | H3: PEAK HOURLY DEMAND | J3: TOTAL OBSERVATIONS
B4: =SUM('Original Data'!N2:N1001) -> 4921 | D4: =SUM(Sheet45[cnt]) -> 58304 | F4: =AVERAGE(Sheet45[cnt]) -> 58.304 | H4: =MAX(Sheet45[cnt]) -> 249 | J4: =COUNT(Sheet45[instant]) -> 1000
A7: 1. Demand Breakdown & Calculated Metrics by User Type
A8: Metric / Indicator | B8: Casual Users | C8: Registered Users | D8: Total Demand
A9: Total Ride Volume | B9: =SUM(Sheet45[casual]) -> 4921 | C9: =SUM(Sheet45[registered]) -> 53383 | D9: =SUM(Sheet45[cnt]) -> 58304
A10: Demand Share (%) | B10: =B9/D9 -> 0.084402442 | C10: =C9/D9 -> 0.91559756 | D10: =D9/D9 -> 1
A11: Average Demand / Hour | B11: =AVERAGE(Sheet45[casual]) -> 4.921 | C11: =AVERAGE(Sheet45[registered]) -> 53.383 | D11: =AVERAGE(Sheet45[cnt]) -> 58.304
A12: Std Deviation (STDEV.S) | B12: =_xlfn.STDEV.S(Sheet45[casual]) -> 7.6438988 | C12: =_xlfn.STDEV.S(Sheet45[registered]) -> 47.893968 | D12: =_xlfn.STDEV.S(Sheet45[cnt]) -> 50.985558
A13: Casual-to-Registered Ratio | B13: =B9/C9 -> 0.092182905 | D13: -
A16: 2. User Demand Summary by Weather Condition (SUMIF, COUNTIF, STDEV)
A17: Weather Condition | B17: Observations (Hrs) | C17: Casual Rides | D17: Registered Rides | E17: Total Demand | F17: Avg Demand / Hr
A18: Clear | B18: =COUNTIF(Sheet45[Weathers],A18) -> 606 | C18: =SUMIF(Sheet45[Weathers],A18,Sheet45[casual]) -> 3211 | D18: =SUMIF(Sheet45[Weathers],A18,Sheet45[registered]) -> 34162 | E18: =SUMIF(Sheet45[Weathers],A18,Sheet45[cnt]) -> 37373 | F18: =IFERROR(E18/B18,0) -> 61.671617
A19: Mist | B19: =COUNTIF(Sheet45[Weathers],A19) -> 309 | C19: =SUMIF(Sheet45[Weathers],A19,Sheet45[casual]) -> 1538 | D19: =SUMIF(Sheet45[Weathers],A19,Sheet45[registered]) -> 16568 | E19: =SUMIF(Sheet45[Weathers],A19,Sheet45[cnt]) -> 18106 | F19: =IFERROR(E19/B19,0) -> 58.595469
A20: Light rain/snow | B20: =COUNTIF(Sheet45[Weathers],A20) -> 84 | C20: =SUMIF(Sheet45[Weathers],A20,Sheet45[casual]) -> 171 | D20: =SUMIF(Sheet45[Weathers],A20,Sheet45[registered]) -> 2618 | E20: =SUMIF(Sheet45[Weathers],A20,Sheet45[cnt]) -> 2789 | F20: =IFERROR(E20/B20,0) -> 33.202381
A21: Heavy rain/snow | B21: =COUNTIF(Sheet45[Weathers],A21) -> 1 | C21: =SUMIF(Sheet45[Weathers],A21,Sheet45[casual]) -> 1 | D21: =SUMIF(Sheet45[Weathers],A21,Sheet45[registered]) -> 35 | E21: =SUMIF(Sheet45[Weathers],A21,Sheet45[cnt]) -> 36 | F21: =IFERROR(E21/B21,0) -> 36
A22: Total / Summary | B22: =SUM(B18:B20) -> 999 | C22: =SUM(C18:C21) -> 4921 | D22: =SUM(D18:D21) -> 53383 | E22: =SUM(E18:E21) -> 58304 | F22: =IFERROR(E22/B22,0) -> 58.362362
A25: 3. Hourly Demand Patterns (Time of Day 0–23 Hours)
A26: Hour of Day | B26: Hourly Obs | C26: Casual Demand | D26: Registered Demand | E26: Total Demand | F26: Peak Hour Index
A27: 0 | B27: =COUNTIF('Original Data'!$F$2:$F$1001,A27) -> 43 | C27: =SUMIF('Original Data'!F2:F1001,A27,'Original Data'!N2:N1001) -> 74 | D27: =SUMIF(Sheet45[Hours],A27,Sheet45[registered]) -> 629 | E27: =SUMIF(Sheet45[Hours],A27,Sheet45[cnt]) -> 703 | F27: =E27/MAX($E$27:$E$50) -> 0.11395688
A28: 1 | B28: =COUNTIF('Original Data'!$F$2:$F$1001,A28) -> 43 | C28: =SUMIF('Original Data'!F3:F1002,A28,'Original Data'!N3:N1002) -> 48 | D28: =SUMIF(Sheet45[Hours],A28,Sheet45[registered]) -> 412 | E28: =SUMIF(Sheet45[Hours],A28,Sheet45[cnt]) -> 460 | F28: =E28/MAX($E$27:$E$50) -> 0.07456638
A29: 2 | B29: =COUNTIF('Original Data'!$F$2:$F$1001,A29) -> 41 | C29: =SUMIF('Original Data'!F4:F1003,A29,'Original Data'!N4:N1003) -> 33 | D29: =SUMIF(Sheet45[Hours],A29,Sheet45[registered]) -> 261 | E29: =SUMIF(Sheet45[Hours],A29,Sheet45[cnt]) -> 294 | F29: =E29/MAX($E$27:$E$50) -> 0.047657643
A30: 3 | B30: =COUNTIF('Original Data'!$F$2:$F$1001,A30) -> 31 | C30: =SUMIF('Original Data'!F5:F1004,A30,'Original Data'!N5:N1004) -> 34 | D30: =SUMIF(Sheet45[Hours],A30,Sheet45[registered]) -> 117 | E30: =SUMIF(Sheet45[Hours],A30,Sheet45[cnt]) -> 151 | F30: =E30/MAX($E$27:$E$50) -> 0.024477225
A31: 4 | B31: =COUNTIF('Original Data'!$F$2:$F$1001,A31) -> 32 | C31: =SUMIF('Original Data'!F6:F1005,A31,'Original Data'!N6:N1005) -> 7 | D31: =SUMIF(Sheet45[Hours],A31,Sheet45[registered]) -> 62 | E31: =SUMIF(Sheet45[Hours],A31,Sheet45[cnt]) -> 69 | F31: =E31/MAX($E$27:$E$50) -> 0.011184957
A32: 5 | B32: =COUNTIF('Original Data'!$F$2:$F$1001,A32) -> 39 | C32: =SUMIF('Original Data'!F7:F1006,A32,'Original Data'!N7:N1006) -> 3 | D32: =SUMIF(Sheet45[Hours],A32,Sheet45[registered]) -> 161 | E32: =SUMIF(Sheet45[Hours],A32,Sheet45[cnt]) -> 164 | F32: =E32/MAX($E$27:$E$50) -> 0.026584536
A33: 6 | B33: =COUNTIF('Original Data'!$F$2:$F$1001,A33) -> 42 | C33: =SUMIF('Original Data'!F8:F1007,A33,'Original Data'!N8:N1007) -> 21 | D33: =SUMIF(Sheet45[Hours],A33,Sheet45[registered]) -> 801 | E33: =SUMIF(Sheet45[Hours],A33,Sheet45[cnt]) -> 822 | F33: =E33/MAX($E$27:$E$50) -> 0.13324688
A34: 7 | B34: =COUNTIF('Original Data'!$F$2:$F$1001,A34) -> 43 | C34: =SUMIF('Original Data'!F9:F1008,A34,'Original Data'!N9:N1008) -> 64 | D34: =SUMIF(Sheet45[Hours],A34,Sheet45[registered]) -> 2275 | E34: =SUMIF(Sheet45[Hours],A34,Sheet45[cnt]) -> 2339 | F34: =E34/MAX($E$27:$E$50) -> 0.37915383
A35: 8 | B35: =COUNTIF('Original Data'!$F$2:$F$1001,A35) -> 42 | C35: =SUMIF('Original Data'!F10:F1009,A35,'Original Data'!N10:N1009) -> 127 | D35: =SUMIF(Sheet45[Hours],A35,Sheet45[registered]) -> 5261 | E35: =SUMIF(Sheet45[Hours],A35,Sheet45[cnt]) -> 5388 | F35: =E35/MAX($E$27:$E$50) -> 0.87339925
A36: 9 | B36: =COUNTIF('Original Data'!$F$2:$F$1001,A36) -> 42 | C36: =SUMIF('Original Data'!F11:F1010,A36,'Original Data'!N11:N1010) -> 172 | D36: =SUMIF(Sheet45[Hours],A36,Sheet45[registered]) -> 3500 | E36: =SUMIF(Sheet45[Hours],A36,Sheet45[cnt]) -> 3672 | F36: =E36/MAX($E$27:$E$50) -> 0.59523424
A37: 10 | B37: =COUNTIF('Original Data'!$F$2:$F$1001,A37) -> 42 | C37: =SUMIF('Original Data'!F12:F1011,A37,'Original Data'!N12:N1011) -> 216 | D37: =SUMIF(Sheet45[Hours],A37,Sheet45[registered]) -> 2037 | E37: =SUMIF(Sheet45[Hours],A37,Sheet45[cnt]) -> 2253 | F37: =E37/MAX($E$27:$E$50) -> 0.36521316
A38: 11 | B38: =COUNTIF('Original Data'!$F$2:$F$1001,A38) -> 42 | C38: =SUMIF('Original Data'!F13:F1012,A38,'Original Data'!N13:N1012) -> 367 | D38: =SUMIF(Sheet45[Hours],A38,Sheet45[registered]) -> 2127 | E38: =SUMIF(Sheet45[Hours],A38,Sheet45[cnt]) -> 2494 | F38: =E38/MAX($E$27:$E$50) -> 0.40427946
... A45: 18 | B45: =COUNTIF('Original Data'!$F$2:$F$1001,A45) -> 43 | C45: =SUMIF('Original Data'!F20:F1019,A45,'Original Data'!N20:N1019) -> 222 | D45: =SUMIF(Sheet45[Hours],A45,Sheet45[registered]) -> 5061 | E45: =SUMIF(Sheet45[Hours],A45,Sheet45[cnt]) -> 5283 | F45: =E45/MAX($E$27:$E$50) -> 0.85637867
A46: 19 | B46: =COUNTIF('Original Data'!$F$2:$F$1001,A46) -> 43 | C46: =SUMIF('Original Data'!F20:F1019,A46,'Original Data'!N20:N1019) -> 187 | D46: =SUMIF(Sheet45[Hours],A46,Sheet45[registered]) -> 3474 | E46: =SUMIF(Sheet45[Hours],A46,Sheet45[cnt]) -> 3661 | F46: =E46/MAX($E$27:$E$50) -> 0.59345113
A47: 20 | B47: =COUNTIF('Original Data'!$F$2:$F$1001,A47) -> 43 | C47: =SUMIF('Original Data'!F21:F1020,A47,'Original Data'!N21:N1020) -> 140 | D47: =SUMIF(Sheet45[Hours],A47,Sheet45[registered]) -> 2516 | E47: =SUMIF(Sheet45[Hours],A47,Sheet45[cnt]) -> 2656 | F47: =E47/MAX($E$27:$E$50) -> 0.4305398
A48: 21 | B48: =COUNTIF('Original Data'!$F$2:$F$1001,A48) -> 43 | C48: =SUMIF('Original Data'!F22:F1021,A48,'Original Data'!N22:N1021) -> 117 | D48: =SUMIF(Sheet45[Hours],A48,Sheet45[registered]) -> 1879 | E48: =SUMIF(Sheet45[Hours],A48,Sheet45[cnt]) -> 1996 | F48: =E48/MAX($E$27:$E$50) -> 0.32355325
A49: 22 | B49: =COUNTIF('Original Data'!$F$2:$F$1001,A49) -> 43 | C49: =SUMIF('Original Data'!F23:F1022,A49,'Original Data'!N23:N1022) -> 103 | D49: =SUMIF(Sheet45[Hours],A49,Sheet45[registered]) -> 1405 | E49: =SUMIF(Sheet45[Hours],A49,Sheet45[cnt]) -> 1508 | F49: =E49/MAX($E$27:$E$50) -> 0.24444805
A50: 23 | B50: =COUNTIF('Original Data'!$F$2:$F$1001,A50) -> 43 | C50: =SUMIF('Original Data'!F24:F1023,A50,'Original Data'!N24:N1023) -> 101 | D50: =SUMIF(Sheet45[Hours],A50,Sheet45[registered]) -> 982 | E50: =SUMIF(Sheet45[Hours],A50,Sheet45[cnt]) -> 1083 | F50: =E50/MAX($E$27:$E$50) -> 0.1755552
A51: Total / Summary | B51: =SUM(B27:B50) -> 1000 | C51: =SUM(C27:C50) -> 4921 | D51: =SUM(D27:D50) -> 53383 | E51: =SUM(E27:E50) -> 58304
A54: 4. Advanced Statistical Indicators & Correlation Matrix (STDEV, CORREL, COUNTIF, SUMIF) | F54: Statistical Indicators Matrix
A55: Statistical Indicator / Relationship | B55: Formula Applied | C55: Calculated Result | D55: Analytical Insight | F55: Temp | H55: atemp | J55: hum | L55: windspeed | N55: casual | P55: registered | R55: cnt
A56: Overall Demand Dispersion | B56: =_xlfn.STDEV.S(Sheet45[cnt]) -> 50.985558 | C56: =_xlfn.STDEV.S(Sheet45[cnt]) -> 50.985558 | D56: High variability in hourly demand across peak vs off-peak hours
...

Sheet pivot chart
H2: Rental Hours | I2: Sum of cnt
H3: 0 | I3: 703
A4: Season | B4: Sum of cnt | H4: 1 | I4: 460
A5: 1 | B5: 58304 | H5: 2 | I5: 294
A6: Grand Total | B6: 58304 | H6: 3 | I6: 151
H7: 4 | I7: 69
H8: 5 | I8: 164
H9: 6 | I9: 822
H10: 7 | I10: 2339
H11: 8 | I11: 5388
H12: 9 | I12: 3672
H13: 10 | I13: 2253
H14: 11 | I14: 2494
H15: 12 | I15: 3283
A16: Sum of registered | B16: Sum of casual | H16: 13 | I16: 3376
A17: 53383 | B17: 4921 | H17: 14 | I17: 3200
H18: 15 | I18: 3352
H19: 16 | I19: 3928
H20: 17 | I20: 6169
H21: 18 | I21: 5283
H22: 19 | I22: 3661
H23: 20 | I23: 2656
H24: 21 | I24: 1996
H25: 22 | I25: 1508
H26: 23 | I26: 1083
H27: Grand Total | I27: 58304
H30: Holiday Vs Non-Holiday | I30: Sum of cnt
H31: FALSE | I31: 57304
H32: TRUE | I32: 1000
H33: Grand Total | I33: 58304
A35: Weekday | B35: Sum of cnt
A36: Sunday | B36: 8121
A37: Monday | B37: 8450
A38: Tuesday | B38: 8383
A39: Wednesday | B39: 8049
A40: Friday | B40: 9095
A41: Saturday | B41: 7748
A42: Thrusday | B42: 8458
A43: Grand Total | B43: 58304
J47: Weathers | K47: Sum of cnt
...

Sheet   Forecast & Anomaly 
A1: Rental by hours for Forecasting
A2: Rental Hours | B2: Sum of cnt | C2: Forecast(Sum of cnt) | D2: Lower Confidence Bound(Sum of cnt) | E2: Upper Confidence Bound(Sum of cnt)
A3: 0 | B3: 703
A4: 1 | B4: 460
A5: 2 | B5: 294
A6: 3 | B6: 151
A7: 4 | B7: 69
A8: 5 | B8: 164
A9: 6 | B9: 822
A10: 7 | B10: 2339
A11: 8 | B11: 5388
A12: 9 | B12: 3672
A13: 10 | B13: 2253
A14: 11 | B14: 2494
... A25: 22 | B25: 1508
A26: 23 | B26: 1083 | C26: 1083 | D26: 1083 | E26: 1083
A27: 24 | C27: =_xlfn.FORECAST.ETS(A27,$B$3:$B$26,$A$3:$A$26,1,1) -> 1207.6791 | D27: =C27-_xlfn.FORECAST.ETS.CONFINT(A27,$B$3:$B$26,$A$3:$A$26,0.95,1,1) -> -1220.8145 | E27: =C27+_xlfn.FORECAST.ETS.CONFINT(A27,$B$3:$B$26,$A$3:$A$26,0.95,1,1) -> 3636.1727
A28: 25 | C28: =_xlfn.FORECAST.ETS(A28,$B$3:$B$26,$A$3:$A$26,1,1) -> 1332.3583 | D28: =C28-_xlfn.FORECAST.ETS.CONFINT(A28,$B$3:$B$26,$A$3:$A$26,0.95,1,1) -> -2100.3335 | E28: =C28+_xlfn.FORECAST.ETS.CONFINT(A28,$B$3:$B$26,$A$3:$A$26,0.95,1,1) -> 4765.0501
A29: 26 | C29: =_xlfn.FORECAST.ETS(A29,$B$3:$B$26,$A$3:$A$26,1,1) -> 1457.0374 | D29: =C29-_xlfn.FORECAST.ETS.CONFINT(A29,$B$3:$B$26,$A$3:$A$26,0.95,1,1) -> -2747.8353 | E29: =C29+_xlfn.FORECAST.ETS.CONFINT(A29,$B$3:$B$26,$A$3:$A$26,0.95,1,1) -> 5661.9101
A30: 27 | C30: =_xlfn.FORECAST.ETS(A30,$B$3:$B$26,$A$3:$A$26,1,1) -> 1581.7165 | D30: =C30-_xlfn.FORECAST.ETS.CONFINT(A30,$B$3:$B$26,$A$3:$A$26,0.95,1,1) -> -3275.2719 | E30: =C30+_xlfn.FORECAST.ETS.CONFINT(A30,$B$3:$B$26,$A$3:$A$26,0.95,1,1) -> 6438.7049
A31: 28 | C31: =_xlfn.FORECAST.ETS(A31,$B$3:$B$26,$A$3:$A$26,1,1) -> 1706.3957 | D31: =C31-_xlfn.FORECAST.ETS.CONFINT(A31,$B$3:$B$26,$A$3:$A$26,0.95,1,1) -> -3726.056 | E31: =C31+_xlfn.FORECAST.ETS.CONFINT(A31,$B$3:$B$26,$A$3:$A$26,0.95,1,1) -> 7138.8473
A32: 29 | C32: =_xlfn.FORECAST.ETS(A32,$B$3:$B$26,$A$3:$A$26,1,1) -> 1831.0748 | D32: =C32-_xlfn.FORECAST.ETS.CONFINT(A32,$B$3:$B$26,$A$3:$A$26,0.95,1,1) -> -4122.4579 | E32: =C32+_xlfn.FORECAST.ETS.CONFINT(A32,$B$3:$B$26,$A$3:$A$26,0.95,1,1) -> 7784.6074
A33: 30 | C33: =_xlfn.FORECAST.ETS(A33,$B$3:$B$26,$A$3:$A$26,1,1) -> 1955.7539 | D33: =C33-_xlfn.FORECAST.ETS.CONFINT(A33,$B$3:$B$26,$A$3:$A$26,0.95,1,1) -> -4477.7061 | E33: =C33+_xlfn.FORECAST.ETS.CONFINT(A33,$B$3:$B$26,$A$3:$A$26,0.95,1,1) -> 8389.2139
A34: 31 | C34: =_xlfn.FORECAST.ETS(A34,$B$3:$B$26,$A$3:$A$26,1,1) -> 2080.433 | D34: =C34-_xlfn.FORECAST.ETS.CONFINT(A34,$B$3:$B$26,$A$3:$A$26,0.95,1,1) -> -4800.418 | E34: =C34+_xlfn.FORECAST.ETS.CONFINT(A34,$B$3:$B$26,$A$3:$A$26,0.95,1,1) -> 8961.2841
A35: 32 | C35: =_xlfn.FORECAST.ETS(A35,$B$3:$B$26,$A$3:$A$26,1,1) -> 2205.1122 | D35: =C35-_xlfn.FORECAST.ETS.CONFINT(A35,$B$3:$B$26,$A$3:$A$26,0.95,1,1) -> -5096.5778 | E35: =C35+_xlfn.FORECAST.ETS.CONFINT(A35,$B$3:$B$26,$A$3:$A$26,0.95,1,1) -> 9506.8021
A36: 33 | C36: =_xlfn.FORECAST.ETS(A36,$B$3:$B$26,$A$3:$A$26,1,1) -> 2329.7913 | D36: =C36-_xlfn.FORECAST.ETS.CONFINT(A36,$B$3:$B$26,$A$3:$A$26,0.95,1,1) -> -5370.5407 | E36: =C36+_xlfn.FORECAST.ETS.CONFINT(A36,$B$3:$B$26,$A$3:$A$26,0.95,1,1) -> 10030.123
A37: 34 | C37: =_xlfn.FORECAST.ETS(A37,$B$3:$B$26,$A$3:$A$26,1,1) -> 2454.4704 | D37: =C37-_xlfn.FORECAST.ETS.CONFINT(A37,$B$3:$B$26,$A$3:$A$26,0.95,1,1) -> -5625.5934 | E37: =C37+_xlfn.FORECAST.ETS.CONFINT(A37,$B$3:$B$26,$A$3:$A$26,0.95,1,1) -> 10534.534
A38: 35 | C38: =_xlfn.FORECAST.ETS(A38,$B$3:$B$26,$A$3:$A$26,1,1) -> 2579.1496 | D38: =C38-_xlfn.FORECAST.ETS.CONFINT(A38,$B$3:$B$26,$A$3:$A$26,0.95,1,1) -> -5864.2886 | E38: =C38+_xlfn.FORECAST.ETS.CONFINT(A38,$B$3:$B$26,$A$3:$A$26,0.95,1,1) -> 11022.588
A39: 36 | C39: =_xlfn.FORECAST.ETS(A39,$B$3:$B$26,$A$3:$A$26,1,1) -> 2703.8287 | D39: =C39-_xlfn.FORECAST.ETS.CONFINT(A39,$B$3:$B$26,$A$3:$A$26,0.95,1,1) -> -6088.655 | E39: =C39+_xlfn.FORECAST.ETS.CONFINT(A39,$B$3:$B$26,$A$3:$A$26,0.95,1,1) -> 11496.312
A41: Anomaly Detection
B42: Rental | C42: Registered | D42: Casual
A43: Q0 (Mini Value) | B43: =_xlfn.QUARTILE.INC(Sheet45[cnt],0) -> 1 | C43: =_xlfn.QUARTILE.INC(Sheet45[registered],0) -> 0 | D43: =_xlfn.QUARTILE.INC(Sheet45[casual],0) -> 0
A44: Q1 | B44: =_xlfn.QUARTILE.INC(Sheet45[cnt],1) -> 16 | C44: =_xlfn.QUARTILE.INC(Sheet45[registered],1) -> 15 | D44: =_xlfn.QUARTILE.INC(Sheet45[casual],1) -> 0
A45: Q2 | B45: =_xlfn.QUARTILE.INC(Sheet45[cnt],2) -> 49 | C45: =_xlfn.QUARTILE.INC(Sheet45[registered],2) -> 46 | D45: =_xlfn.QUARTILE.INC(Sheet45[casual],2) -> 3
A46: Q3 | B46: =_xlfn.QUARTILE.INC(Sheet45[cnt],3) -> 83 | C46: =_xlfn.QUARTILE.INC(Sheet45[registered],3) -> 74 | D46: =_xlfn.QUARTILE.INC(Sheet45[casual],3) -> 6
A47: Q4(Max Value) | B47: =_xlfn.QUARTILE.INC(Sheet45[cnt],4) -> 249 | C47: =_xlfn.QUARTILE.INC(Sheet45[registered],4) -> 247 | D47: =_xlfn.QUARTILE.INC(Sheet45[casual],4) -> 62
A48: IQR | B48: =B46-B44 -> 67 | C48: =C46-C44 -> 59 | D48: =D46-D44 -> 6
A49: Lower Limit | B49: =B44-1.5*67 -> -84.5 | C49: =C44-1.5*C48 -> -73.5 | D49: =D44-1.5*D48 -> -9
A50: Upper Limit | B50: =B46+1.5*B48 -> 183.5 | C50: =C46+1.5*C48 -> 162.5 | D50: =D46+1.5*D48 -> 15

Sheet Dashboard
B1: BIKE SHARING USER DEMAND ANALYSIS DASHBOARD
